2019-01-20 17:04:56 basehttp.log_message: "GET /goods/info/1 HTTP/1.1" 301 0
2019-01-20 17:05:49 basehttp.log_message: "GET /goods/info/1 HTTP/1.1" 301 0
2019-01-20 17:06:03 basehttp.log_message: "GET /goods/info/2 HTTP/1.1" 301 0
2019-01-20 17:06:07 basehttp.log_message: "GET /goods/info HTTP/1.1" 301 0
2019-01-20 17:06:40 log.log_response: Internal Server Error: /goods/info/
Traceback (most recent call last):
  File "D:\Program Files\Python37\lib\site-packages\django\contrib\sessions\backends\base.py", line 190, in _get_session
    return self._session_cache
AttributeError: 'SessionStore' object has no attribute '_session_cache'

During handling of the above exception, another exception occurred:

Traceback (most recent call last):
  File "D:\Program Files\Python37\lib\site-packages\django\db\backends\utils.py", line 85, in _execute
    return self.cursor.execute(sql, params)
  File "D:\Program Files\Python37\lib\site-packages\django\db\backends\mysql\base.py", line 71, in execute
    return self.cursor.execute(query, args)
  File "D:\Program Files\Python37\lib\site-packages\pymysql\cursors.py", line 170, in execute
    result = self._query(query)
  File "D:\Program Files\Python37\lib\site-packages\pymysql\cursors.py", line 328, in _query
    conn.query(q)
  File "D:\Program Files\Python37\lib\site-packages\pymysql\connections.py", line 516, in query
    self._affected_rows = self._read_query_result(unbuffered=unbuffered)
  File "D:\Program Files\Python37\lib\site-packages\pymysql\connections.py", line 727, in _read_query_result
    result.read()
  File "D:\Program Files\Python37\lib\site-packages\pymysql\connections.py", line 1066, in read
    first_packet = self.connection._read_packet()
  File "D:\Program Files\Python37\lib\site-packages\pymysql\connections.py", line 683, in _read_packet
    packet.check_error()
  File "D:\Program Files\Python37\lib\site-packages\pymysql\protocol.py", line 220, in check_error
    err.raise_mysql_exception(self._data)
  File "D:\Program Files\Python37\lib\site-packages\pymysql\err.py", line 109, in raise_mysql_exception
    raise errorclass(errno, errval)
pymysql.err.ProgrammingError: (1146, "Table 'jd_notebook.django_session' doesn't exist")

The above exception was the direct cause of the following exception:

Traceback (most recent call last):
  File "D:\Program Files\Python37\lib\site-packages\django\core\handlers\exception.py", line 34, in inner
    response = get_response(request)
  File "D:\Program Files\Python37\lib\site-packages\django\core\handlers\base.py", line 126, in _get_response
    response = self.process_exception_by_middleware(e, request)
  File "D:\Program Files\Python37\lib\site-packages\django\core\handlers\base.py", line 124, in _get_response
    response = wrapped_callback(request, *callback_args, **callback_kwargs)
  File "D:\Program Files\Python37\lib\site-packages\django\views\decorators\csrf.py", line 54, in wrapped_view
    return view_func(*args, **kwargs)
  File "D:\Program Files\Python37\lib\site-packages\rest_framework\viewsets.py", line 116, in view
    return self.dispatch(request, *args, **kwargs)
  File "D:\Program Files\Python37\lib\site-packages\rest_framework\views.py", line 495, in dispatch
    response = self.handle_exception(exc)
  File "D:\Program Files\Python37\lib\site-packages\rest_framework\views.py", line 455, in handle_exception
    self.raise_uncaught_exception(exc)
  File "D:\Program Files\Python37\lib\site-packages\rest_framework\views.py", line 483, in dispatch
    self.initial(request, *args, **kwargs)
  File "D:\Program Files\Python37\lib\site-packages\rest_framework\views.py", line 400, in initial
    self.perform_authentication(request)
  File "D:\Program Files\Python37\lib\site-packages\rest_framework\views.py", line 326, in perform_authentication
    request.user
  File "D:\Program Files\Python37\lib\site-packages\rest_framework\request.py", line 223, in user
    self._authenticate()
  File "D:\Program Files\Python37\lib\site-packages\rest_framework\request.py", line 376, in _authenticate
    user_auth_tuple = authenticator.authenticate(self)
  File "D:\Program Files\Python37\lib\site-packages\rest_framework\authentication.py", line 126, in authenticate
    if not user or not user.is_active:
  File "D:\Program Files\Python37\lib\site-packages\django\utils\functional.py", line 213, in inner
    self._setup()
  File "D:\Program Files\Python37\lib\site-packages\django\utils\functional.py", line 347, in _setup
    self._wrapped = self._setupfunc()
  File "D:\Program Files\Python37\lib\site-packages\django\contrib\auth\middleware.py", line 24, in <lambda>
    request.user = SimpleLazyObject(lambda: get_user(request))
  File "D:\Program Files\Python37\lib\site-packages\django\contrib\auth\middleware.py", line 12, in get_user
    request._cached_user = auth.get_user(request)
  File "D:\Program Files\Python37\lib\site-packages\django\contrib\auth\__init__.py", line 182, in get_user
    user_id = _get_user_session_key(request)
  File "D:\Program Files\Python37\lib\site-packages\django\contrib\auth\__init__.py", line 59, in _get_user_session_key
    return get_user_model()._meta.pk.to_python(request.session[SESSION_KEY])
  File "D:\Program Files\Python37\lib\site-packages\django\contrib\sessions\backends\base.py", line 55, in __getitem__
    return self._session[key]
  File "D:\Program Files\Python37\lib\site-packages\django\contrib\sessions\backends\base.py", line 195, in _get_session
    self._session_cache = self.load()
  File "D:\Program Files\Python37\lib\site-packages\django\contrib\sessions\backends\db.py", line 43, in load
    s = self._get_session_from_db()
  File "D:\Program Files\Python37\lib\site-packages\django\contrib\sessions\backends\db.py", line 34, in _get_session_from_db
    expire_date__gt=timezone.now()
  File "D:\Program Files\Python37\lib\site-packages\django\db\models\manager.py", line 82, in manager_method
    return getattr(self.get_queryset(), name)(*args, **kwargs)
  File "D:\Program Files\Python37\lib\site-packages\django\db\models\query.py", line 393, in get
    num = len(clone)
  File "D:\Program Files\Python37\lib\site-packages\django\db\models\query.py", line 250, in __len__
    self._fetch_all()
  File "D:\Program Files\Python37\lib\site-packages\django\db\models\query.py", line 1186, in _fetch_all
    self._result_cache = list(self._iterable_class(self))
  File "D:\Program Files\Python37\lib\site-packages\django\db\models\query.py", line 54, in __iter__
    results = compiler.execute_sql(chunked_fetch=self.chunked_fetch, chunk_size=self.chunk_size)
  File "D:\Program Files\Python37\lib\site-packages\django\db\models\sql\compiler.py", line 1065, in execute_sql
    cursor.execute(sql, params)
  File "D:\Program Files\Python37\lib\site-packages\django\db\backends\utils.py", line 100, in execute
    return super().execute(sql, params)
  File "D:\Program Files\Python37\lib\site-packages\django\db\backends\utils.py", line 68, in execute
    return self._execute_with_wrappers(sql, params, many=False, executor=self._execute)
  File "D:\Program Files\Python37\lib\site-packages\django\db\backends\utils.py", line 77, in _execute_with_wrappers
    return executor(sql, params, many, context)
  File "D:\Program Files\Python37\lib\site-packages\django\db\backends\utils.py", line 85, in _execute
    return self.cursor.execute(sql, params)
  File "D:\Program Files\Python37\lib\site-packages\django\db\utils.py", line 89, in __exit__
    raise dj_exc_value.with_traceback(traceback) from exc_value
  File "D:\Program Files\Python37\lib\site-packages\django\db\backends\utils.py", line 85, in _execute
    return self.cursor.execute(sql, params)
  File "D:\Program Files\Python37\lib\site-packages\django\db\backends\mysql\base.py", line 71, in execute
    return self.cursor.execute(query, args)
  File "D:\Program Files\Python37\lib\site-packages\pymysql\cursors.py", line 170, in execute
    result = self._query(query)
  File "D:\Program Files\Python37\lib\site-packages\pymysql\cursors.py", line 328, in _query
    conn.query(q)
  File "D:\Program Files\Python37\lib\site-packages\pymysql\connections.py", line 516, in query
    self._affected_rows = self._read_query_result(unbuffered=unbuffered)
  File "D:\Program Files\Python37\lib\site-packages\pymysql\connections.py", line 727, in _read_query_result
    result.read()
  File "D:\Program Files\Python37\lib\site-packages\pymysql\connections.py", line 1066, in read
    first_packet = self.connection._read_packet()
  File "D:\Program Files\Python37\lib\site-packages\pymysql\connections.py", line 683, in _read_packet
    packet.check_error()
  File "D:\Program Files\Python37\lib\site-packages\pymysql\protocol.py", line 220, in check_error
    err.raise_mysql_exception(self._data)
  File "D:\Program Files\Python37\lib\site-packages\pymysql\err.py", line 109, in raise_mysql_exception
    raise errorclass(errno, errval)
django.db.utils.ProgrammingError: (1146, "Table 'jd_notebook.django_session' doesn't exist")
2019-01-20 17:06:40 basehttp.log_message: "GET /goods/info/ HTTP/1.1" 500 287388
2019-01-20 17:10:15 log.log_response: Not Found: /
2019-01-20 17:10:15 basehttp.log_message: "GET / HTTP/1.1" 404 2034
2019-01-20 17:10:35 log.log_response: Internal Server Error: /goods/info/
Traceback (most recent call last):
  File "D:\Program Files\Python37\lib\site-packages\django\contrib\sessions\backends\base.py", line 190, in _get_session
    return self._session_cache
AttributeError: 'SessionStore' object has no attribute '_session_cache'

During handling of the above exception, another exception occurred:

Traceback (most recent call last):
  File "D:\Program Files\Python37\lib\site-packages\django\db\backends\utils.py", line 85, in _execute
    return self.cursor.execute(sql, params)
  File "D:\Program Files\Python37\lib\site-packages\django\db\backends\mysql\base.py", line 71, in execute
    return self.cursor.execute(query, args)
  File "D:\Program Files\Python37\lib\site-packages\pymysql\cursors.py", line 170, in execute
    result = self._query(query)
  File "D:\Program Files\Python37\lib\site-packages\pymysql\cursors.py", line 328, in _query
    conn.query(q)
  File "D:\Program Files\Python37\lib\site-packages\pymysql\connections.py", line 516, in query
    self._affected_rows = self._read_query_result(unbuffered=unbuffered)
  File "D:\Program Files\Python37\lib\site-packages\pymysql\connections.py", line 727, in _read_query_result
    result.read()
  File "D:\Program Files\Python37\lib\site-packages\pymysql\connections.py", line 1066, in read
    first_packet = self.connection._read_packet()
  File "D:\Program Files\Python37\lib\site-packages\pymysql\connections.py", line 683, in _read_packet
    packet.check_error()
  File "D:\Program Files\Python37\lib\site-packages\pymysql\protocol.py", line 220, in check_error
    err.raise_mysql_exception(self._data)
  File "D:\Program Files\Python37\lib\site-packages\pymysql\err.py", line 109, in raise_mysql_exception
    raise errorclass(errno, errval)
pymysql.err.ProgrammingError: (1146, "Table 'jd_notebook.django_session' doesn't exist")

The above exception was the direct cause of the following exception:

Traceback (most recent call last):
  File "D:\Program Files\Python37\lib\site-packages\django\core\handlers\exception.py", line 34, in inner
    response = get_response(request)
  File "D:\Program Files\Python37\lib\site-packages\django\core\handlers\base.py", line 126, in _get_response
    response = self.process_exception_by_middleware(e, request)
  File "D:\Program Files\Python37\lib\site-packages\django\core\handlers\base.py", line 124, in _get_response
    response = wrapped_callback(request, *callback_args, **callback_kwargs)
  File "D:\Program Files\Python37\lib\site-packages\django\views\decorators\csrf.py", line 54, in wrapped_view
    return view_func(*args, **kwargs)
  File "D:\Program Files\Python37\lib\site-packages\rest_framework\viewsets.py", line 116, in view
    return self.dispatch(request, *args, **kwargs)
  File "D:\Program Files\Python37\lib\site-packages\rest_framework\views.py", line 495, in dispatch
    response = self.handle_exception(exc)
  File "D:\Program Files\Python37\lib\site-packages\rest_framework\views.py", line 455, in handle_exception
    self.raise_uncaught_exception(exc)
  File "D:\Program Files\Python37\lib\site-packages\rest_framework\views.py", line 483, in dispatch
    self.initial(request, *args, **kwargs)
  File "D:\Program Files\Python37\lib\site-packages\rest_framework\views.py", line 400, in initial
    self.perform_authentication(request)
  File "D:\Program Files\Python37\lib\site-packages\rest_framework\views.py", line 326, in perform_authentication
    request.user
  File "D:\Program Files\Python37\lib\site-packages\rest_framework\request.py", line 223, in user
    self._authenticate()
  File "D:\Program Files\Python37\lib\site-packages\rest_framework\request.py", line 376, in _authenticate
    user_auth_tuple = authenticator.authenticate(self)
  File "D:\Program Files\Python37\lib\site-packages\rest_framework\authentication.py", line 126, in authenticate
    if not user or not user.is_active:
  File "D:\Program Files\Python37\lib\site-packages\django\utils\functional.py", line 213, in inner
    self._setup()
  File "D:\Program Files\Python37\lib\site-packages\django\utils\functional.py", line 347, in _setup
    self._wrapped = self._setupfunc()
  File "D:\Program Files\Python37\lib\site-packages\django\contrib\auth\middleware.py", line 24, in <lambda>
    request.user = SimpleLazyObject(lambda: get_user(request))
  File "D:\Program Files\Python37\lib\site-packages\django\contrib\auth\middleware.py", line 12, in get_user
    request._cached_user = auth.get_user(request)
  File "D:\Program Files\Python37\lib\site-packages\django\contrib\auth\__init__.py", line 182, in get_user
    user_id = _get_user_session_key(request)
  File "D:\Program Files\Python37\lib\site-packages\django\contrib\auth\__init__.py", line 59, in _get_user_session_key
    return get_user_model()._meta.pk.to_python(request.session[SESSION_KEY])
  File "D:\Program Files\Python37\lib\site-packages\django\contrib\sessions\backends\base.py", line 55, in __getitem__
    return self._session[key]
  File "D:\Program Files\Python37\lib\site-packages\django\contrib\sessions\backends\base.py", line 195, in _get_session
    self._session_cache = self.load()
  File "D:\Program Files\Python37\lib\site-packages\django\contrib\sessions\backends\db.py", line 43, in load
    s = self._get_session_from_db()
  File "D:\Program Files\Python37\lib\site-packages\django\contrib\sessions\backends\db.py", line 34, in _get_session_from_db
    expire_date__gt=timezone.now()
  File "D:\Program Files\Python37\lib\site-packages\django\db\models\manager.py", line 82, in manager_method
    return getattr(self.get_queryset(), name)(*args, **kwargs)
  File "D:\Program Files\Python37\lib\site-packages\django\db\models\query.py", line 393, in get
    num = len(clone)
  File "D:\Program Files\Python37\lib\site-packages\django\db\models\query.py", line 250, in __len__
    self._fetch_all()
  File "D:\Program Files\Python37\lib\site-packages\django\db\models\query.py", line 1186, in _fetch_all
    self._result_cache = list(self._iterable_class(self))
  File "D:\Program Files\Python37\lib\site-packages\django\db\models\query.py", line 54, in __iter__
    results = compiler.execute_sql(chunked_fetch=self.chunked_fetch, chunk_size=self.chunk_size)
  File "D:\Program Files\Python37\lib\site-packages\django\db\models\sql\compiler.py", line 1065, in execute_sql
    cursor.execute(sql, params)
  File "D:\Program Files\Python37\lib\site-packages\django\db\backends\utils.py", line 100, in execute
    return super().execute(sql, params)
  File "D:\Program Files\Python37\lib\site-packages\django\db\backends\utils.py", line 68, in execute
    return self._execute_with_wrappers(sql, params, many=False, executor=self._execute)
  File "D:\Program Files\Python37\lib\site-packages\django\db\backends\utils.py", line 77, in _execute_with_wrappers
    return executor(sql, params, many, context)
  File "D:\Program Files\Python37\lib\site-packages\django\db\backends\utils.py", line 85, in _execute
    return self.cursor.execute(sql, params)
  File "D:\Program Files\Python37\lib\site-packages\django\db\utils.py", line 89, in __exit__
    raise dj_exc_value.with_traceback(traceback) from exc_value
  File "D:\Program Files\Python37\lib\site-packages\django\db\backends\utils.py", line 85, in _execute
    return self.cursor.execute(sql, params)
  File "D:\Program Files\Python37\lib\site-packages\django\db\backends\mysql\base.py", line 71, in execute
    return self.cursor.execute(query, args)
  File "D:\Program Files\Python37\lib\site-packages\pymysql\cursors.py", line 170, in execute
    result = self._query(query)
  File "D:\Program Files\Python37\lib\site-packages\pymysql\cursors.py", line 328, in _query
    conn.query(q)
  File "D:\Program Files\Python37\lib\site-packages\pymysql\connections.py", line 516, in query
    self._affected_rows = self._read_query_result(unbuffered=unbuffered)
  File "D:\Program Files\Python37\lib\site-packages\pymysql\connections.py", line 727, in _read_query_result
    result.read()
  File "D:\Program Files\Python37\lib\site-packages\pymysql\connections.py", line 1066, in read
    first_packet = self.connection._read_packet()
  File "D:\Program Files\Python37\lib\site-packages\pymysql\connections.py", line 683, in _read_packet
    packet.check_error()
  File "D:\Program Files\Python37\lib\site-packages\pymysql\protocol.py", line 220, in check_error
    err.raise_mysql_exception(self._data)
  File "D:\Program Files\Python37\lib\site-packages\pymysql\err.py", line 109, in raise_mysql_exception
    raise errorclass(errno, errval)
django.db.utils.ProgrammingError: (1146, "Table 'jd_notebook.django_session' doesn't exist")
2019-01-20 17:10:35 basehttp.log_message: "GET /goods/info/ HTTP/1.1" 500 287390
2019-01-20 17:24:18 log.log_response: Not Found: /
2019-01-20 17:24:18 basehttp.log_message: "GET / HTTP/1.1" 404 2034
2019-01-20 17:24:33 log.log_response: Internal Server Error: /goods/info/
Traceback (most recent call last):
  File "D:\Program Files\Python37\lib\site-packages\django\contrib\sessions\backends\base.py", line 190, in _get_session
    return self._session_cache
AttributeError: 'SessionStore' object has no attribute '_session_cache'

During handling of the above exception, another exception occurred:

Traceback (most recent call last):
  File "D:\Program Files\Python37\lib\site-packages\django\db\backends\utils.py", line 85, in _execute
    return self.cursor.execute(sql, params)
  File "D:\Program Files\Python37\lib\site-packages\django\db\backends\mysql\base.py", line 71, in execute
    return self.cursor.execute(query, args)
  File "D:\Program Files\Python37\lib\site-packages\pymysql\cursors.py", line 170, in execute
    result = self._query(query)
  File "D:\Program Files\Python37\lib\site-packages\pymysql\cursors.py", line 328, in _query
    conn.query(q)
  File "D:\Program Files\Python37\lib\site-packages\pymysql\connections.py", line 516, in query
    self._affected_rows = self._read_query_result(unbuffered=unbuffered)
  File "D:\Program Files\Python37\lib\site-packages\pymysql\connections.py", line 727, in _read_query_result
    result.read()
  File "D:\Program Files\Python37\lib\site-packages\pymysql\connections.py", line 1066, in read
    first_packet = self.connection._read_packet()
  File "D:\Program Files\Python37\lib\site-packages\pymysql\connections.py", line 683, in _read_packet
    packet.check_error()
  File "D:\Program Files\Python37\lib\site-packages\pymysql\protocol.py", line 220, in check_error
    err.raise_mysql_exception(self._data)
  File "D:\Program Files\Python37\lib\site-packages\pymysql\err.py", line 109, in raise_mysql_exception
    raise errorclass(errno, errval)
pymysql.err.ProgrammingError: (1146, "Table 'jd_notebook1.django_session' doesn't exist")

The above exception was the direct cause of the following exception:

Traceback (most recent call last):
  File "D:\Program Files\Python37\lib\site-packages\django\core\handlers\exception.py", line 34, in inner
    response = get_response(request)
  File "D:\Program Files\Python37\lib\site-packages\django\core\handlers\base.py", line 126, in _get_response
    response = self.process_exception_by_middleware(e, request)
  File "D:\Program Files\Python37\lib\site-packages\django\core\handlers\base.py", line 124, in _get_response
    response = wrapped_callback(request, *callback_args, **callback_kwargs)
  File "D:\Program Files\Python37\lib\site-packages\django\views\decorators\csrf.py", line 54, in wrapped_view
    return view_func(*args, **kwargs)
  File "D:\Program Files\Python37\lib\site-packages\rest_framework\viewsets.py", line 116, in view
    return self.dispatch(request, *args, **kwargs)
  File "D:\Program Files\Python37\lib\site-packages\rest_framework\views.py", line 495, in dispatch
    response = self.handle_exception(exc)
  File "D:\Program Files\Python37\lib\site-packages\rest_framework\views.py", line 455, in handle_exception
    self.raise_uncaught_exception(exc)
  File "D:\Program Files\Python37\lib\site-packages\rest_framework\views.py", line 483, in dispatch
    self.initial(request, *args, **kwargs)
  File "D:\Program Files\Python37\lib\site-packages\rest_framework\views.py", line 400, in initial
    self.perform_authentication(request)
  File "D:\Program Files\Python37\lib\site-packages\rest_framework\views.py", line 326, in perform_authentication
    request.user
  File "D:\Program Files\Python37\lib\site-packages\rest_framework\request.py", line 223, in user
    self._authenticate()
  File "D:\Program Files\Python37\lib\site-packages\rest_framework\request.py", line 376, in _authenticate
    user_auth_tuple = authenticator.authenticate(self)
  File "D:\Program Files\Python37\lib\site-packages\rest_framework\authentication.py", line 126, in authenticate
    if not user or not user.is_active:
  File "D:\Program Files\Python37\lib\site-packages\django\utils\functional.py", line 213, in inner
    self._setup()
  File "D:\Program Files\Python37\lib\site-packages\django\utils\functional.py", line 347, in _setup
    self._wrapped = self._setupfunc()
  File "D:\Program Files\Python37\lib\site-packages\django\contrib\auth\middleware.py", line 24, in <lambda>
    request.user = SimpleLazyObject(lambda: get_user(request))
  File "D:\Program Files\Python37\lib\site-packages\django\contrib\auth\middleware.py", line 12, in get_user
    request._cached_user = auth.get_user(request)
  File "D:\Program Files\Python37\lib\site-packages\django\contrib\auth\__init__.py", line 182, in get_user
    user_id = _get_user_session_key(request)
  File "D:\Program Files\Python37\lib\site-packages\django\contrib\auth\__init__.py", line 59, in _get_user_session_key
    return get_user_model()._meta.pk.to_python(request.session[SESSION_KEY])
  File "D:\Program Files\Python37\lib\site-packages\django\contrib\sessions\backends\base.py", line 55, in __getitem__
    return self._session[key]
  File "D:\Program Files\Python37\lib\site-packages\django\contrib\sessions\backends\base.py", line 195, in _get_session
    self._session_cache = self.load()
  File "D:\Program Files\Python37\lib\site-packages\django\contrib\sessions\backends\db.py", line 43, in load
    s = self._get_session_from_db()
  File "D:\Program Files\Python37\lib\site-packages\django\contrib\sessions\backends\db.py", line 34, in _get_session_from_db
    expire_date__gt=timezone.now()
  File "D:\Program Files\Python37\lib\site-packages\django\db\models\manager.py", line 82, in manager_method
    return getattr(self.get_queryset(), name)(*args, **kwargs)
  File "D:\Program Files\Python37\lib\site-packages\django\db\models\query.py", line 393, in get
    num = len(clone)
  File "D:\Program Files\Python37\lib\site-packages\django\db\models\query.py", line 250, in __len__
    self._fetch_all()
  File "D:\Program Files\Python37\lib\site-packages\django\db\models\query.py", line 1186, in _fetch_all
    self._result_cache = list(self._iterable_class(self))
  File "D:\Program Files\Python37\lib\site-packages\django\db\models\query.py", line 54, in __iter__
    results = compiler.execute_sql(chunked_fetch=self.chunked_fetch, chunk_size=self.chunk_size)
  File "D:\Program Files\Python37\lib\site-packages\django\db\models\sql\compiler.py", line 1065, in execute_sql
    cursor.execute(sql, params)
  File "D:\Program Files\Python37\lib\site-packages\django\db\backends\utils.py", line 100, in execute
    return super().execute(sql, params)
  File "D:\Program Files\Python37\lib\site-packages\django\db\backends\utils.py", line 68, in execute
    return self._execute_with_wrappers(sql, params, many=False, executor=self._execute)
  File "D:\Program Files\Python37\lib\site-packages\django\db\backends\utils.py", line 77, in _execute_with_wrappers
    return executor(sql, params, many, context)
  File "D:\Program Files\Python37\lib\site-packages\django\db\backends\utils.py", line 85, in _execute
    return self.cursor.execute(sql, params)
  File "D:\Program Files\Python37\lib\site-packages\django\db\utils.py", line 89, in __exit__
    raise dj_exc_value.with_traceback(traceback) from exc_value
  File "D:\Program Files\Python37\lib\site-packages\django\db\backends\utils.py", line 85, in _execute
    return self.cursor.execute(sql, params)
  File "D:\Program Files\Python37\lib\site-packages\django\db\backends\mysql\base.py", line 71, in execute
    return self.cursor.execute(query, args)
  File "D:\Program Files\Python37\lib\site-packages\pymysql\cursors.py", line 170, in execute
    result = self._query(query)
  File "D:\Program Files\Python37\lib\site-packages\pymysql\cursors.py", line 328, in _query
    conn.query(q)
  File "D:\Program Files\Python37\lib\site-packages\pymysql\connections.py", line 516, in query
    self._affected_rows = self._read_query_result(unbuffered=unbuffered)
  File "D:\Program Files\Python37\lib\site-packages\pymysql\connections.py", line 727, in _read_query_result
    result.read()
  File "D:\Program Files\Python37\lib\site-packages\pymysql\connections.py", line 1066, in read
    first_packet = self.connection._read_packet()
  File "D:\Program Files\Python37\lib\site-packages\pymysql\connections.py", line 683, in _read_packet
    packet.check_error()
  File "D:\Program Files\Python37\lib\site-packages\pymysql\protocol.py", line 220, in check_error
    err.raise_mysql_exception(self._data)
  File "D:\Program Files\Python37\lib\site-packages\pymysql\err.py", line 109, in raise_mysql_exception
    raise errorclass(errno, errval)
django.db.utils.ProgrammingError: (1146, "Table 'jd_notebook1.django_session' doesn't exist")
2019-01-20 17:24:33 basehttp.log_message: "GET /goods/info/ HTTP/1.1" 500 287417
